<?xml version="1.0"?>
<robot name="Master_Arm">

  <link name="world"/>

  <!-- Link Base -->

  <link name="MA_Base">
    <inertial>
      <mass value="0.66142136"/>
      <origin rpy="0 0 0" xyz="-0.01624256 0.00000000 -0.0111219"/>
      <inertia ixx="0.00454612" ixy="0.00000000" ixz="-0.00000412" iyy="0.00051668" iyz="-0.00000000" izz="0.00477987"/>
    </inertial>

    <visual>
    <origin xyz="0.0 0.0 0.010"/>
      <geometry>
        <mesh scale="0.001 0.001 0.001" filename="package://master_arm_display_pkg/urdf/meshes/MA_Base.stl"/>
      </geometry>
      <material name="LightGrey">
        <color rgba="0.7 0.7 0.7 1.0"/>
      </material>
    </visual>
  </link>

  <!-- Links_R -->
  <link name="MA_Link_J1R">
    <inertial>
      <mass value="0.23605493"/>
      <origin rpy="0 0 0" xyz="-0.00001991 0.01073585 0.01076106"/>
      <inertia ixx="0.00012008" ixy="-0.00000130" ixz="0.00000047" iyy="0.00011013" iyz="0.00000389" izz="0.00009188"/>
    </inertial>

    <visual>
      <geometry>
        <mesh scale="0.001 0.001 0.001" filename="package://master_arm_display_pkg/urdf/meshes/MA_Link_J1R.stl"/>
      </geometry>
      <material name="LightGrey">
        <color rgba="0.7 0.7 0.7 1.0"/>
      </material>
    </visual>
  </link>


    <link name="MA_Link_J2R">
    <inertial>
      <mass value="0.25778160"/>
      <origin rpy="0 0 0" xyz="0.01309355 -0.00006725 -0.06431642"/>
      <inertia ixx="0.00015925" ixy="-0.00000023" ixz="0.00003240" iyy="0.00021601" iyz="0.00000118" izz="0.00012721"/>
    </inertial>

    <visual>
      <geometry>
        <mesh scale="0.001 0.001 0.001" filename="package://master_arm_display_pkg/urdf/meshes/MA_Link_J2R.stl"/>
      </geometry>
      <material name="LightGrey">
        <color rgba="0.7 0.7 0.7 1.0"/>
      </material>
    </visual>
  </link>


    <link name="MA_Link_J3R">
    <inertial>
      <mass value="0.22100820"/>
      <origin rpy="0 0 0" xyz="0.00674624 0.00016256 -0.16285715"/>
      <inertia ixx="0.00033024" ixy="-0.00000031" ixz="0.00007099" iyy="0.00037963" iyz="0.00000124" izz="0.00009326"/>
    </inertial>

    <visual>
      <geometry>
        <mesh scale="0.001 0.001 0.001" filename="package://master_arm_display_pkg/urdf/meshes/MA_Link_J3R.stl"/>
      </geometry>
      <material name="LightGrey">
        <color rgba="0.7 0.7 0.7 1.0"/>
      </material>
    </visual>
  </link>


    <link name="MA_Link_J4R">
    <inertial>
      <mass value="0.16661372"/>
      <origin rpy="0 0 0" xyz="-0.02113496 -0.00005349 -0.04166261"/>
      <inertia ixx="0.00006868" ixy="-0.00000015" ixz="-0.00000275" iyy="0.00007370" iyz="0.00000003" izz="0.00006647"/>
    </inertial>

    <visual>
      <geometry>
        <mesh scale="0.001 0.001 0.001" filename="package://master_arm_display_pkg/urdf/meshes/MA_Link_J4R.stl"/>
      </geometry>
      <material name="LightGrey">
        <color rgba="0.7 0.7 0.7 1.0"/>
      </material>
    </visual>
  </link>


    <link name="MA_Link_J5R">
    <inertial>
      <mass value="0.22488687"/>
      <origin rpy="0 0 0" xyz="0.00316462 0.00015984 0.03638073"/>
      <inertia ixx="0.00040375" ixy="-0.00000049" ixz="-0.00004970" iyy="0.00043616" iyz="0.00000136" izz="0.00007691"/>
    </inertial>

    <visual>
      <geometry>
        <mesh scale="0.001 0.001 0.001" filename="package://master_arm_display_pkg/urdf/meshes/MA_Link_J5R.stl"/>
      </geometry>
      <material name="LightGrey">
        <color rgba="0.7 0.7 0.7 1.0"/>
      </material>
    </visual>
  </link>


    <link name="MA_Link_J6R">
    <inertial>
      <mass value="0.16285880"/>
      <origin rpy="0 0 0" xyz="0.00841219 0.00000000 -0.05539566"/>
      <inertia ixx="0.00007773" ixy="-0.00000000" ixz="0.00000622" iyy="0.00008163" iyz="0.00000000" izz="0.00006271"/>
    </inertial>

    <visual>
      <geometry>
        <mesh scale="0.001 0.001 0.001" filename="package://master_arm_display_pkg/urdf/meshes/MA_Link_J6R.stl"/>
      </geometry>
      <material name="LightGrey">
        <color rgba="0.7 0.7 0.7 1.0"/>
      </material>
    </visual>
  </link>


    <link name="MA_Link_J7R">
    <inertial>
      <mass value="0.19"/>
      <origin rpy="0 0 0" xyz="-0.01808597 0.00684039 -0.10439675"/>
      <inertia ixx="0.00060848" ixy="0.00002390" ixz="0.00021011" iyy="0.00077882" iyz="-0.00003139" izz="0.00026207"/>
    </inertial>

    <visual>
      <geometry>
        <mesh scale="0.001 0.001 0.001" filename="package://master_arm_display_pkg/urdf/meshes/MA_Link_J7R.stl"/>
      </geometry>
      <material name="LightGrey">
        <color rgba="0.7 0.7 0.7 1.0"/>
      </material>
    </visual>
  </link>




  
  <!-- Links_L -->
      <link name="MA_Link_J1L">
    <inertial>
      <mass value="0.23605493"/>
      <origin rpy="0 0 0" xyz="-0.00001991 -0.01073585 0.01076106"/>
      <inertia ixx="0.00012008" ixy="0.00000130" ixz="0.00000047" iyy="0.00011013" iyz="-0.00000389" izz="0.00009188"/>
    </inertial>

    <visual>
      <geometry>
        <mesh scale="0.001 0.001 0.001" filename="package://master_arm_display_pkg/urdf/meshes/MA_Link_J1L.stl" />
      </geometry>
      <material name="LightGrey">
        <color rgba="0.7 0.7 0.7 1.0"/>
      </material>
    </visual>
  </link>


    <link name="MA_Link_J2L">
    <inertial>
      <mass value="0.25778160"/>
      <origin rpy="0 0 0" xyz="0.01309355 0.00006725 -0.06431642"/>
      <inertia ixx="0.00015925" ixy="0.00000023" ixz="0.00003240" iyy="0.00021601" iyz="-0.00000118" izz="0.00012721"/>
    </inertial>

    <visual>
      <geometry>
        <mesh scale="0.001 0.001 0.001" filename="package://master_arm_display_pkg/urdf/meshes/MA_Link_J2L.stl" />
      </geometry>
      <material name="LightGrey">
        <color rgba="0.7 0.7 0.7 1.0"/>
      </material>
    </visual>
  </link>


      <link name="MA_Link_J3L">
    <inertial>
      <mass value="0.22100820"/>
      <origin rpy="0 0 0" xyz="0.00674624 -0.00016256 -0.16285715"/>
      <inertia ixx="0.00033024" ixy="0.00000031" ixz="0.00007099" iyy="0.00037963" iyz="-0.00000124" izz="0.00009326"/>
    </inertial>

    <visual>
      <geometry>
        <mesh scale="0.001 0.001 0.001" filename="package://master_arm_display_pkg/urdf/meshes/MA_Link_J3L.stl" />
      </geometry>
      <material name="LightGrey">
        <color rgba="0.7 0.7 0.7 1.0"/>
      </material>
    </visual>
  </link>


      <link name="MA_Link_J4L">
    <inertial>
      <mass value="0.16661372"/>
      <origin rpy="0 0 0" xyz="-0.02113496 0.00005349 -0.04166261"/>
      <inertia ixx="0.00006868" ixy="0.00000015" ixz="-0.00000275" iyy="0.00007370" iyz="-0.00000003" izz="0.00006647"/>
    </inertial>

    <visual>
      <geometry>
        <mesh scale="0.001 0.001 0.001" filename="package://master_arm_display_pkg/urdf/meshes/MA_Link_J4L.stl" />
      </geometry>
      <material name="LightGrey">
        <color rgba="0.7 0.7 0.7 1.0"/>
      </material>
    </visual>
  </link>


      <link name="MA_Link_J5L">
    <inertial>
      <mass value="0.22488687"/>
      <origin rpy="0 0 0" xyz="0.00316462 -0.00015984 0.03638073"/>
      <inertia ixx="0.00040375" ixy="0.00000049" ixz="0.00004970" iyy="0.00043616" iyz="-0.00000136" izz="0.00007691"/>
    </inertial>

    <visual>
      <geometry>
        <mesh scale="0.001 0.001 0.001" filename="package://master_arm_display_pkg/urdf/meshes/MA_Link_J5L.stl" />
      </geometry>
      <material name="LightGrey">
        <color rgba="0.7 0.7 0.7 1.0"/>
      </material>
    </visual>
  </link>


      <link name="MA_Link_J6L">
    <inertial>
      <mass value="0.16285880"/>
      <origin rpy="0 0 0" xyz="0.00841219 -0.00000000 -0.05539566"/>
      <inertia ixx="0.00007773" ixy="0.00000000" ixz="0.00000622" iyy="0.00008163" iyz="-0.00000000" izz="0.00006271"/>
    </inertial>

    <visual>
      <geometry>
        <mesh scale="0.001 0.001 0.001" filename="package://master_arm_display_pkg/urdf/meshes/MA_Link_J6L.stl" />
      </geometry>
      <material name="LightGrey">
        <color rgba="0.7 0.7 0.7 1.0"/>
      </material>
    </visual>
  </link>


    <link name="MA_Link_J7L">
    <inertial>
      <mass value="0.19"/>
      <origin rpy="0 0 0" xyz="-0.01808597 0.00684039 -0.10439675"/>
      <inertia ixx="0.00060848" ixy="0.00002390" ixz="0.00021011" iyy="0.00077882" iyz="-0.00003139" izz="0.00026207"/>
    </inertial>

    <visual>
      <geometry>
        <mesh scale="0.001 0.001 0.001" filename="package://master_arm_display_pkg/urdf/meshes/MA_Link_J7L.stl" />
      </geometry>
      <material name="LightGrey">
        <color rgba="0.7 0.7 0.7 1.0"/>
      </material>
    </visual>
  </link>




    <!-- Joints -->
  <joint name="world_joint" type="fixed">
    <parent link="world"/>
    <child link="MA_Base"/>
    <origin rpy="0.0 0.0 0.0" xyz="0.0 0.0 0.0"/>
    <axis xyz="0 0 0"/>
  </joint>


    <!-- Joints_R -->
  <joint name="J1_Shoulder_Pitch" type="revolute">
    <parent link="MA_Base"/>
    <child link="MA_Link_J1R"/>
    <origin rpy="0.0 0.0 0.0" xyz="0.0 -0.450 0.01"/>
    <axis xyz="0.0 0.93969262 -0.34202014"/>
    <limit effort="1000.0" lower="-3.14159265" upper="3.14159265" velocity="3.14159265"/>
  </joint>

  <joint name="J2_Shoulder_Roll" type="revolute">
    <parent link="MA_Link_J1R"/>
    <child link="MA_Link_J2R"/>
    <origin rpy="0.0 0.0 0.0" xyz="0.0 0.0 0.0"/>
    <axis xyz="1 0 0"/>
    <limit effort="1000.0" lower="-2.356194488" upper="0.174532925" velocity="3.14159265"/>
  </joint>

  <joint name="J3_Shoulder_Yaw" type="revolute">
    <parent link="MA_Link_J2R"/>
    <child link="MA_Link_J3R"/>
    <origin rpy="0.0 0.0 0.0" xyz="0.0 0.0 0.0"/>
    <axis xyz="0 0 1"/>
    <limit effort="1000.0" lower="-2.705260338" upper="2.705260338" velocity="3.14159265"/>
  </joint>

    <joint name="J4_Elbow_Pitch" type="revolute">
    <parent link="MA_Link_J3R"/>
    <child link="MA_Link_J4R"/>
    <origin rpy="0.0 0.0 0.0" xyz="0.032 0.0 -0.350"/>
    <axis xyz="0 1 0"/>
    <limit effort="1000.0" lower="-3.054326190" upper="0.087266463" velocity="3.14159265"/>
  </joint>

    <joint name="J4_Wrist_Yaw1" type="revolute">
    <parent link="MA_Link_J4R"/>
    <child link="MA_Link_J5R"/>
    <origin rpy="0.0 0.0 0.0" xyz="-0.032 0.0 -0.250"/>
    <axis xyz="0 0 1"/>
    <limit effort="1000.0" lower="-2.705260338" upper="2.705260338" velocity="3.14159265"/>
  </joint>

    <joint name="J5_Wrist_Pitch" type="revolute">
    <parent link="MA_Link_J5R"/>
    <child link="MA_Link_J6R"/>
    <origin rpy="0.0 0.0 0.0" xyz="0.0 0.0 0.0"/>
    <axis xyz="0 1 0"/>
    <limit effort="1000.0" lower="-2.268928025" upper="2.0943951" velocity="3.14159265"/>
  </joint>

    <joint name="J6_Wrist_Yaw2" type="revolute">
    <parent link="MA_Link_J6R"/>
    <child link="MA_Link_J7R"/>
    <origin rpy="0.0 0.0 0.0" xyz="0.0 0.0 0.0"/>
    <axis xyz="0 0 1"/>
    <limit effort="1000.0" lower="-3.14159265" upper="3.14159265" velocity="3.14159265"/>
  </joint>


    <!-- Joints_L -->
  <joint name="J7_Shoulder_Pitch" type="revolute">
    <parent link="MA_Base"/>
    <child link="MA_Link_J1L"/>
    <origin rpy="0.0 0.0 0.0" xyz="0.0 0.450 0.01"/>
    <axis xyz="0.0 0.93969262 0.34202014"/>
    <limit effort="1000.0" lower="-3.14159265" upper="3.14159265" velocity="3.14159265"/>
  </joint>

  <joint name="J8_Shoulder_Roll" type="revolute">
    <parent link="MA_Link_J1L"/>
    <child link="MA_Link_J2L"/>
    <origin rpy="0.0 0.0 0.0" xyz="0.0 0.0 0.0"/>
    <axis xyz="1 0 0"/>
    <limit effort="1000.0" lower="-0.174532925" upper="2.356194488" velocity="3.14159265"/>
  </joint>

  <joint name="J9_Shoulder_Yaw" type="revolute">
    <parent link="MA_Link_J2L"/>
    <child link="MA_Link_J3L"/>
    <origin rpy="0.0 0.0 0.0" xyz="0.0 0.0 0.0"/>
    <axis xyz="0 0 1"/>
    <limit effort="1000.0" lower="-2.705260338" upper="2.705260338" velocity="3.14159265"/>
  </joint>

    <joint name="J10_Elbow" type="revolute">
    <parent link="MA_Link_J3L"/>
    <child link="MA_Link_J4L"/>
    <origin rpy="0.0 0.0 0.0" xyz="0.032 0.0 -0.350"/>
    <axis xyz="0 1 0"/>
    <limit effort="1000.0" lower="-3.054326190" upper="0.087266463" velocity="3.14159265"/>
  </joint>

    <joint name="J11_Wrist_Yaw1" type="revolute">
    <parent link="MA_Link_J4L"/>
    <child link="MA_Link_J5L"/>
    <origin rpy="0.0 0.0 0.0" xyz="-0.032 0.0 -0.250"/>
    <axis xyz="0 0 1"/>
    <limit effort="1000.0" lower="-2.705260338" upper="2.705260338" velocity="3.14159265"/>
  </joint>

    <joint name="J12_Wrist_Pitch" type="revolute">
    <parent link="MA_Link_J5L"/>
    <child link="MA_Link_J6L"/>
    <origin rpy="0.0 0.0 0.0" xyz="0.0 0.0 0.0"/>
    <axis xyz="0 1 0"/>
    <limit effort="1000.0" lower="-2.268928025" upper="2.0943951" velocity="3.14159265"/>
  </joint>

    <joint name="J13_Wrist_Yaw2" type="revolute">
    <parent link="MA_Link_J6L"/>
    <child link="MA_Link_J7L"/>
    <origin rpy="0.0 0.0 0.0" xyz="0.0 0.0 0.0"/>
    <axis xyz="0 0 1"/>
    <limit effort="1000.0" lower="-3.14159265" upper="3.14159265" velocity="3.14159265"/>
  </joint>

</robot>